<?xml version="1.0" ?>
<robot name="drone" xmlns:xacro="http://www.ros.org/wiki/xacro">

<xacro:include filename="$(find drone_description)/urdf/materials.xacro" />
<xacro:include filename="$(find drone_description)/urdf/drone.trans" />
<xacro:include filename="$(find drone_description)/gazebo/drone_materials.gazebo" />
<xacro:include filename="$(find drone_description)/gazebo/drone_physics.gazebo" />
<xacro:include filename="$(find drone_description)/gazebo/drone_plugins.gazebo" />
<link name="base_link">
  <inertial>
    <origin rpy="0 0 0" xyz="0.0 0.002156211479160986 0.0163651441638259"/>
    <mass value="0.8291720950994419"/>
    <inertia ixx="0.009648" ixy="-0.0" ixz="0.0" iyy="0.009574" iyz="-8.8e-05" izz="0.018496"/>
  </inertial>
  <visual>
    <origin rpy="0 0 0" xyz="0 0 0"/>
    <geometry>
      <mesh filename="package://drone_description/meshes/base_link.stl" scale="0.001 0.001 0.001"/>
    </geometry>
    <material name="silver_default"/>
  </visual>
  <collision>
    <origin rpy="0 0 0" xyz="0 0 0"/>
    <geometry>
      <mesh filename="package://drone_description/meshes/base_link.stl" scale="0.001 0.001 0.001"/>
    </geometry>
  </collision>
</link>

<link name="propeller_bright_1">
  <inertial>
    <origin rpy="0 0 0" xyz="5.759433296947947e-08 -1.3530083598722875e-05 0.0015000003406627008"/>
    <mass value="0.0015994551812686354"/>
    <inertia ixx="0.0" ixy="0.0" ixz="0.0" iyy="3e-06" iyz="0.0" izz="3e-06"/>
  </inertial>
  <visual>
    <origin rpy="0 0 0" xyz="-0.212132 -0.212132 -0.025"/>
    <geometry>
      <mesh filename="package://drone_description/meshes/propeller_bright_1.stl" scale="0.001 0.001 0.001"/>
    </geometry>
    <material name="silver_default"/>
  </visual>
  <collision>
    <origin rpy="0 0 0" xyz="-0.212132 -0.212132 -0.025"/>
    <geometry>
      <mesh filename="package://drone_description/meshes/propeller_bright_1.stl" scale="0.001 0.001 0.001"/>
    </geometry>
  </collision>
</link>

<link name="propeller_fright_1">
  <inertial>
    <origin rpy="0 0 0" xyz="1.1117505915869685e-08 1.353008359869512e-05 0.001499999659337281"/>
    <mass value="0.0015994551812686354"/>
    <inertia ixx="0.0" ixy="0.0" ixz="0.0" iyy="3e-06" iyz="0.0" izz="3e-06"/>
  </inertial>
  <visual>
    <origin rpy="0 0 0" xyz="-0.212132 0.212132 -0.025"/>
    <geometry>
      <mesh filename="package://drone_description/meshes/propeller_fright_1.stl" scale="0.001 0.001 0.001"/>
    </geometry>
    <material name="silver_default"/>
  </visual>
  <collision>
    <origin rpy="0 0 0" xyz="-0.212132 0.212132 -0.025"/>
    <geometry>
      <mesh filename="package://drone_description/meshes/propeller_fright_1.stl" scale="0.001 0.001 0.001"/>
    </geometry>
  </collision>
</link>

<link name="propeller_fleft_1">
  <inertial>
    <origin rpy="0 0 0" xyz="-5.759433296947947e-08 1.3530083598722875e-05 0.0015000003406627008"/>
    <mass value="0.0015994551812686354"/>
    <inertia ixx="0.0" ixy="0.0" ixz="-0.0" iyy="3e-06" iyz="-0.0" izz="3e-06"/>
  </inertial>
  <visual>
    <origin rpy="0 0 0" xyz="0.212132 0.212132 -0.025"/>
    <geometry>
      <mesh filename="package://drone_description/meshes/propeller_fleft_1.stl" scale="0.001 0.001 0.001"/>
    </geometry>
    <material name="silver_default"/>
  </visual>
  <collision>
    <origin rpy="0 0 0" xyz="0.212132 0.212132 -0.025"/>
    <geometry>
      <mesh filename="package://drone_description/meshes/propeller_fleft_1.stl" scale="0.001 0.001 0.001"/>
    </geometry>
  </collision>
</link>

<link name="propeller_bleft_1">
  <inertial>
    <origin rpy="0 0 0" xyz="-1.1117505915869685e-08 -1.3530083598722875e-05 0.001499999659337281"/>
    <mass value="0.0015994551812686354"/>
    <inertia ixx="0.0" ixy="0.0" ixz="-0.0" iyy="3e-06" iyz="-0.0" izz="3e-06"/>
  </inertial>
  <visual>
    <origin rpy="0 0 0" xyz="0.212132 -0.212132 -0.025"/>
    <geometry>
      <mesh filename="package://drone_description/meshes/propeller_bleft_1.stl" scale="0.001 0.001 0.001"/>
    </geometry>
    <material name="silver_default"/>
  </visual>
  <collision>
    <origin rpy="0 0 0" xyz="0.212132 -0.212132 -0.025"/>
    <geometry>
      <mesh filename="package://drone_description/meshes/propeller_bleft_1.stl" scale="0.001 0.001 0.001"/>
    </geometry>
  </collision>
</link>

<link name="stopper_fright_1">
  <inertial>
    <origin rpy="0 0 0" xyz="3.4355672251518143e-08 -3.435596435119592e-08 -0.0020344827586206427"/>
    <mass value="0.00016945750773462672"/>
    <inertia ixx="0.0" ixy="0.0" ixz="-0.0" iyy="0.0" iyz="0.0" izz="0.0"/>
  </inertial>
  <visual>
    <origin rpy="0 0 0" xyz="-0.212132 0.212132 -0.035"/>
    <geometry>
      <mesh filename="package://drone_description/meshes/stopper_fright_1.stl" scale="0.001 0.001 0.001"/>
    </geometry>
    <material name="silver_default"/>
  </visual>
  <collision>
    <origin rpy="0 0 0" xyz="-0.212132 0.212132 -0.035"/>
    <geometry>
      <mesh filename="package://drone_description/meshes/stopper_fright_1.stl" scale="0.001 0.001 0.001"/>
    </geometry>
  </collision>
</link>

<link name="stopper_bright_1">
  <inertial>
    <origin rpy="0 0 0" xyz="3.4355672251518143e-08 3.4355964323440347e-08 -0.0020344827586206427"/>
    <mass value="0.00016945750773462675"/>
    <inertia ixx="0.0" ixy="-0.0" ixz="-0.0" iyy="0.0" iyz="-0.0" izz="0.0"/>
  </inertial>
  <visual>
    <origin rpy="0 0 0" xyz="-0.212132 -0.212132 -0.035"/>
    <geometry>
      <mesh filename="package://drone_description/meshes/stopper_bright_1.stl" scale="0.001 0.001 0.001"/>
    </geometry>
    <material name="silver_default"/>
  </visual>
  <collision>
    <origin rpy="0 0 0" xyz="-0.212132 -0.212132 -0.035"/>
    <geometry>
      <mesh filename="package://drone_description/meshes/stopper_bright_1.stl" scale="0.001 0.001 0.001"/>
    </geometry>
  </collision>
</link>

<link name="stopper_fleft_1">
  <inertial>
    <origin rpy="0 0 0" xyz="-3.4355672251518143e-08 -3.4355964323440347e-08 -0.0020344827586206427"/>
    <mass value="0.00016945750773462675"/>
    <inertia ixx="0.0" ixy="-0.0" ixz="0.0" iyy="0.0" iyz="0.0" izz="0.0"/>
  </inertial>
  <visual>
    <origin rpy="0 0 0" xyz="0.212132 0.212132 -0.035"/>
    <geometry>
      <mesh filename="package://drone_description/meshes/stopper_fleft_1.stl" scale="0.001 0.001 0.001"/>
    </geometry>
    <material name="silver_default"/>
  </visual>
  <collision>
    <origin rpy="0 0 0" xyz="0.212132 0.212132 -0.035"/>
    <geometry>
      <mesh filename="package://drone_description/meshes/stopper_fleft_1.stl" scale="0.001 0.001 0.001"/>
    </geometry>
  </collision>
</link>

<link name="stopper_bleft_1">
  <inertial>
    <origin rpy="0 0 0" xyz="-3.4355672251518143e-08 3.4355964323440347e-08 -0.0020344827586206427"/>
    <mass value="0.00016945750773462672"/>
    <inertia ixx="0.0" ixy="0.0" ixz="0.0" iyy="0.0" iyz="-0.0" izz="0.0"/>
  </inertial>
  <visual>
    <origin rpy="0 0 0" xyz="0.212132 -0.212132 -0.035"/>
    <geometry>
      <mesh filename="package://drone_description/meshes/stopper_bleft_1.stl" scale="0.001 0.001 0.001"/>
    </geometry>
    <material name="silver_default"/>
  </visual>
  <collision>
    <origin rpy="0 0 0" xyz="0.212132 -0.212132 -0.035"/>
    <geometry>
      <mesh filename="package://drone_description/meshes/stopper_bleft_1.stl" scale="0.001 0.001 0.001"/>
    </geometry>
  </collision>
</link>

<link name="motor_fright_1">
  <inertial>
    <origin rpy="0 0 0" xyz="3.435596171441624e-08 -3.435596435119592e-08 0.010074626865671642"/>
    <mass value="0.3157300616857739"/>
    <inertia ixx="6e-05" ixy="0.0" ixz="-0.0" iyy="6e-05" iyz="0.0" izz="9.8e-05"/>
  </inertial>
  <visual>
    <origin rpy="0 0 0" xyz="-0.212132 0.212132 -0.005"/>
    <geometry>
      <mesh filename="package://drone_description/meshes/motor_fright_1.stl" scale="0.001 0.001 0.001"/>
    </geometry>
    <material name="silver_default"/>
  </visual>
  <collision>
    <origin rpy="0 0 0" xyz="-0.212132 0.212132 -0.005"/>
    <geometry>
      <mesh filename="package://drone_description/meshes/motor_fright_1.stl" scale="0.001 0.001 0.001"/>
    </geometry>
  </collision>
</link>

<link name="motor_bright_1">
  <inertial>
    <origin rpy="0 0 0" xyz="3.43559656279524e-08 3.4355964323440347e-08 0.010074626865671645"/>
    <mass value="0.3157300616857742"/>
    <inertia ixx="6e-05" ixy="0.0" ixz="-0.0" iyy="6e-05" iyz="0.0" izz="9.8e-05"/>
  </inertial>
  <visual>
    <origin rpy="0 0 0" xyz="-0.212132 -0.212132 -0.005"/>
    <geometry>
      <mesh filename="package://drone_description/meshes/motor_bright_1.stl" scale="0.001 0.001 0.001"/>
    </geometry>
    <material name="silver_default"/>
  </visual>
  <collision>
    <origin rpy="0 0 0" xyz="-0.212132 -0.212132 -0.005"/>
    <geometry>
      <mesh filename="package://drone_description/meshes/motor_bright_1.stl" scale="0.001 0.001 0.001"/>
    </geometry>
  </collision>
</link>

<link name="motor_bleft_1">
  <inertial>
    <origin rpy="0 0 0" xyz="-3.435596171441624e-08 3.4355964323440347e-08 0.010074626865671642"/>
    <mass value="0.3157300616857739"/>
    <inertia ixx="6e-05" ixy="-0.0" ixz="0.0" iyy="6e-05" iyz="0.0" izz="9.8e-05"/>
  </inertial>
  <visual>
    <origin rpy="0 0 0" xyz="0.212132 -0.212132 -0.005"/>
    <geometry>
      <mesh filename="package://drone_description/meshes/motor_bleft_1.stl" scale="0.001 0.001 0.001"/>
    </geometry>
    <material name="silver_default"/>
  </visual>
  <collision>
    <origin rpy="0 0 0" xyz="0.212132 -0.212132 -0.005"/>
    <geometry>
      <mesh filename="package://drone_description/meshes/motor_bleft_1.stl" scale="0.001 0.001 0.001"/>
    </geometry>
  </collision>
</link>

<link name="motor_fleft_1">
  <inertial>
    <origin rpy="0 0 0" xyz="-3.43559656279524e-08 -3.4355964323440347e-08 0.010074626865671645"/>
    <mass value="0.3157300616857742"/>
    <inertia ixx="6e-05" ixy="0.0" ixz="0.0" iyy="6e-05" iyz="-0.0" izz="9.8e-05"/>
  </inertial>
  <visual>
    <origin rpy="0 0 0" xyz="0.212132 0.212132 -0.005"/>
    <geometry>
      <mesh filename="package://drone_description/meshes/motor_fleft_1.stl" scale="0.001 0.001 0.001"/>
    </geometry>
    <material name="silver_default"/>
  </visual>
  <collision>
    <origin rpy="0 0 0" xyz="0.212132 0.212132 -0.005"/>
    <geometry>
      <mesh filename="package://drone_description/meshes/motor_fleft_1.stl" scale="0.001 0.001 0.001"/>
    </geometry>
  </collision>
</link>

<link name="lidar_1">
  <inertial>
    <origin rpy="0 0 0" xyz="-3.618764437576268e-18 -3.469446951953614e-18 0.009999999999999995"/>
    <mass value="0.3082687791334984"/>
    <inertia ixx="5.8e-05" ixy="-0.0" ixz="-0.0" iyy="5.8e-05" iyz="-0.0" izz="9.6e-05"/>
  </inertial>
  <visual>
    <origin rpy="0 0 0" xyz="-0.0 -0.03 -0.08"/>
    <geometry>
      <mesh filename="package://drone_description/meshes/lidar_1.stl" scale="0.001 0.001 0.001"/>
    </geometry>
    <material name="silver_default"/>
  </visual>
  <collision>
    <origin rpy="0 0 0" xyz="-0.0 -0.03 -0.08"/>
    <geometry>
      <mesh filename="package://drone_description/meshes/lidar_1.stl" scale="0.001 0.001 0.001"/>
    </geometry>
  </collision>
</link>

<link name="camera_1">
  <inertial>
    <origin rpy="0 0 0" xyz="0.00038335257158038225 -1.0911410663894117e-14 0.012500000000000053"/>
    <mass value="0.49756104753050334"/>
    <inertia ixx="0.000128" ixy="0.0" ixz="-0.0" iyy="0.000133" iyz="0.0" izz="0.00021"/>
  </inertial>
  <visual>
    <origin rpy="0 0 0" xyz="-0.0 0.03 -0.05"/>
    <geometry>
      <mesh filename="package://drone_description/meshes/camera_1.stl" scale="0.001 0.001 0.001"/>
    </geometry>
    <material name="silver_default"/>
  </visual>
  <collision>
    <origin rpy="0 0 0" xyz="-0.0 0.03 -0.05"/>
    <geometry>
      <mesh filename="package://drone_description/meshes/camera_1.stl" scale="0.001 0.001 0.001"/>
    </geometry>
  </collision>
</link>

<joint name="revolve_bright" type="continuous">
  <origin rpy="0 0 0" xyz="0.0 0.0 0.02"/>
  <parent link="motor_bright_1"/>
  <child link="propeller_bright_1"/>
  <axis xyz="0.0 0.0 1.0"/>
</joint>

<joint name="revolve_fright" type="continuous">
  <origin rpy="0 0 0" xyz="0.0 0.0 0.02"/>
  <parent link="motor_fright_1"/>
  <child link="propeller_fright_1"/>
  <axis xyz="0.0 0.0 1.0"/>
</joint>

<joint name="revolve_fleft" type="continuous">
  <origin rpy="0 0 0" xyz="0.0 0.0 0.02"/>
  <parent link="motor_fleft_1"/>
  <child link="propeller_fleft_1"/>
  <axis xyz="0.0 0.0 1.0"/>
</joint>

<joint name="revolve_bleft" type="continuous">
  <origin rpy="0 0 0" xyz="0.0 0.0 0.02"/>
  <parent link="motor_bleft_1"/>
  <child link="propeller_bleft_1"/>
  <axis xyz="0.0 0.0 1.0"/>
</joint>

<joint name="stopper_rigid_fright" type="fixed">
  <origin rpy="0 0 0" xyz="0.0 0.0 0.03"/>
  <parent link="motor_fright_1"/>
  <child link="stopper_fright_1"/>
</joint>

<joint name="stopper_rigid_bright" type="fixed">
  <origin rpy="0 0 0" xyz="0.0 0.0 0.03"/>
  <parent link="motor_bright_1"/>
  <child link="stopper_bright_1"/>
</joint>

<joint name="stopper_rigid_fleft" type="fixed">
  <origin rpy="0 0 0" xyz="0.0 0.0 0.03"/>
  <parent link="motor_fleft_1"/>
  <child link="stopper_fleft_1"/>
</joint>

<joint name="stopper_rigid_bleft" type="fixed">
  <origin rpy="0 0 0" xyz="0.0 0.0 0.03"/>
  <parent link="motor_bleft_1"/>
  <child link="stopper_bleft_1"/>
</joint>

<joint name="motor_fright_rigid" type="fixed">
  <origin rpy="0 0 0" xyz="0.212132 -0.212132 0.005"/>
  <parent link="base_link"/>
  <child link="motor_fright_1"/>
</joint>

<joint name="motor_bright_rigid" type="fixed">
  <origin rpy="0 0 0" xyz="0.212132 0.212132 0.005"/>
  <parent link="base_link"/>
  <child link="motor_bright_1"/>
</joint>

<joint name="motor_bleft_rigid" type="fixed">
  <origin rpy="0 0 0" xyz="-0.212132 0.212132 0.005"/>
  <parent link="base_link"/>
  <child link="motor_bleft_1"/>
</joint>

<joint name="motor_fleft_rigid" type="fixed">
  <origin rpy="0 0 0" xyz="-0.212132 -0.212132 0.005"/>
  <parent link="base_link"/>
  <child link="motor_fleft_1"/>
</joint>

<joint name="lidar_rigid" type="fixed">
  <origin rpy="0 0 0" xyz="0.0 0.03 0.08"/>
  <parent link="base_link"/>
  <child link="lidar_1"/>
</joint>

<joint name="Rigid24" type="fixed">
  <origin rpy="0 0 0" xyz="0.0 -0.03 0.05"/>
  <parent link="base_link"/>
  <child link="camera_1"/>
</joint>

</robot>
